<?xml version='1.0' encoding='utf-8'?>
<robot name="fr3">
  
  
  
  
  
  
  <link name="base">
      </link>
  <joint name="fr3_base_joint" type="fixed">
    <parent link="base" />
    <child link="fr3_link0" />
    <origin rpy="0 0 0" xyz="0 0 0" />
  </joint>
  
  <link name="fr3_link0">
    <visual name="fr3_link0_visual">
      <geometry>
        <mesh filename="/home/haocheng/kinematics_calibration/meshes/fr3/link0.dae" />
      </geometry>
    </visual>
    <collision name="fr3_link0_collision">
      <geometry>
        <mesh filename="/home/haocheng/kinematics_calibration/meshes/fr3/link0.stl" />
      </geometry>
    </collision>
    <inertial>
      <origin rpy="0 0 0" xyz="-0.0172 0.0004 0.0745" />
      <mass value="2.3966" />
      <inertia ixx="0.009" ixy="0.0" ixz="0.002" iyy="0.0115" iyz="0.0" izz="0.0085" />
    </inertial>
  </link>
  <link name="fr3_link0_sc">
    <collision>
      <origin rpy="0 1.5707963267948966 0" xyz="-0.075 0 0.06" />
      <geometry>
        <cylinder length="0.03" radius="0.09" />
      </geometry>
    </collision>
    <collision>
      <origin xyz="-0.06 0 0.06" />
      <geometry>
        <sphere radius="0.09" />
      </geometry>
    </collision>
    <collision>
      <origin xyz="-0.09 0 0.06" />
      <geometry>
        <sphere radius="0.09" />
      </geometry>
    </collision>
  </link>
  
  <joint name="fr3_link0_sc_joint" type="fixed">
    <origin rpy="0 0 0" />
    <parent link="fr3_link0" />
    <child link="fr3_link0_sc" />
  </joint>
  <link name="fr3_link0_accelerometer_top">
      </link>
  <joint name="fr3_link0_accelerometer_top_joint" type="fixed">
    <origin rpy="3.14159 0 0" xyz="0 0 0.05" />
    <parent link="fr3_link0" />
    <child link="fr3_link0_accelerometer_top" />
  </joint>
  <link name="fr3_link0_accelerometer_bottom">
      </link>
  <joint name="fr3_link0_accelerometer_bottom_joint" type="fixed">
    <origin rpy="0 0 0" xyz="0 0 0.06" />
    <parent link="fr3_link0" />
    <child link="fr3_link0_accelerometer_bottom" />
  </joint>
  
  <link name="fr3_link1">
    <visual name="fr3_link1_visual">
      <geometry>
        <mesh filename="/home/haocheng/kinematics_calibration/meshes/fr3/link1.dae" />
      </geometry>
    </visual>
    <collision name="fr3_link1_collision">
      <geometry>
        <mesh filename="/home/haocheng/kinematics_calibration/meshes/fr3/link1.stl" />
      </geometry>
    </collision>
    <inertial>
      <origin rpy="0 0 0" xyz="0.0000004128 -0.0181251324 -0.0386035970" />
      <mass value="2.9274653454" />
      <inertia ixx="0.023927316485107913" ixy="1.3317903455714081e-05" ixz="-0.00011404774918616684" iyy="0.0224821613275756" iyz="-0.0019950320628240115" izz="0.006350098258530016" />
    </inertial>
  </link>
  <link name="fr3_link1_sc">
    <collision>
      <origin rpy="0 0 0" xyz="0 0 -0.1915" />
      <geometry>
        <cylinder length="0.283" radius="0.09" />
      </geometry>
    </collision>
    <collision>
      <origin xyz="0 0 -0.05000000000000002" />
      <geometry>
        <sphere radius="0.09" />
      </geometry>
    </collision>
    <collision>
      <origin xyz="0 0 -0.33299999999999996" />
      <geometry>
        <sphere radius="0.09" />
      </geometry>
    </collision>
  </link>
  
  <joint name="fr3_link1_sc_joint" type="fixed">
    <origin rpy="0 0 0" />
    <parent link="fr3_link1" />
    <child link="fr3_link1_sc" />
  </joint>
  <link name="fr3_link1_accelerometer_top">
      </link>
  <joint name="fr3_link1_accelerometer_top_joint" type="fixed">
    <origin rpy="1.5708 0 0" xyz="0 -0.1 0.0" />
    <parent link="fr3_link1" />
    <child link="fr3_link1_accelerometer_top" />
  </joint>
  <link name="fr3_link1_accelerometer_bottom">
      </link>
  <joint name="fr3_link1_accelerometer_bottom_joint" type="fixed">
    <origin rpy="-1.5708 0 0" xyz="0 -0.09 0.0" />
    <parent link="fr3_link1" />
    <child link="fr3_link1_accelerometer_bottom" />
  </joint>
  <joint name="fr3_joint1" type="revolute">
    <origin rpy="-6.244163137498879e-19 5.291241641851583e-17 -7.58916466465139e-18" xyz="-2.447164727006978e-17 1.9977949979524458e-17 0.33299999999999996" />
    <parent link="fr3_link0" />
    <child link="fr3_link1" />
    <axis xyz="0 0 1" />
    <limit effort="87.0" lower="-2.9007" upper="2.9007" velocity="2.62" />
    <safety_controller k_position="100.0" k_velocity="40.0" soft_lower_limit="-2.9007" soft_upper_limit="2.9007" />
    <position_based_velocity_limits deceleration_limit="6.0" velocity_offset="0.652" />
    <dynamics D="1" K="7000" damping="0.003" friction="0.2" mu_coulomb="0" mu_viscous="16" />
  </joint>
  
  <link name="fr3_link2">
    <visual name="fr3_link2_visual">
      <geometry>
        <mesh filename="/home/haocheng/kinematics_calibration/meshes/fr3/link2.dae" />
      </geometry>
    </visual>
    <collision name="fr3_link2_collision">
      <geometry>
        <mesh filename="/home/haocheng/kinematics_calibration/meshes/fr3/link2.stl" />
      </geometry>
    </collision>
    <inertial>
      <origin rpy="0 0 0" xyz="0.0031828864 -0.0743221644 0.0088146084" />
      <mass value="2.9355370338" />
      <inertia ixx="0.041938946257609425" ixy="0.00020257331521090626" ixz="0.004077784227179924" iyy="0.02514514885014724" iyz="-0.0042252158006570156" izz="0.06170214472888839" />
    </inertial>
  </link>
  <link name="fr3_link2_sc">
    <collision>
      <origin rpy="0 0 0" xyz="0 0 0" />
      <geometry>
        <cylinder length="0.12" radius="0.09" />
      </geometry>
    </collision>
    <collision>
      <origin xyz="0 0 0.06" />
      <geometry>
        <sphere radius="0.09" />
      </geometry>
    </collision>
    <collision>
      <origin xyz="0 0 -0.06" />
      <geometry>
        <sphere radius="0.09" />
      </geometry>
    </collision>
  </link>
  
  <joint name="fr3_link2_sc_joint" type="fixed">
    <origin rpy="0 0 0" />
    <parent link="fr3_link2" />
    <child link="fr3_link2_sc" />
  </joint>
  <link name="fr3_link2_accelerometer_top">
      </link>
  <joint name="fr3_link2_accelerometer_top_joint" type="fixed">
    <origin rpy="-1.5708 0 0" xyz="0 -0.13 0" />
    <parent link="fr3_link2" />
    <child link="fr3_link2_accelerometer_top" />
  </joint>
  <link name="fr3_link2_accelerometer_bottom">
      </link>
  <joint name="fr3_link2_accelerometer_bottom_joint" type="fixed">
    <origin rpy="1.5708 0 0" xyz="0 -0.14 0" />
    <parent link="fr3_link2" />
    <child link="fr3_link2_accelerometer_bottom" />
  </joint>
  <joint name="fr3_joint2" type="revolute">
    <origin rpy="-1.5715949103692501 0.0027097748375854397 1.3564567549358015e-09" xyz="0.00011848018876511169 0.0007721360704577187 -3.2906633262855086e-17" />
    <parent link="fr3_link1" />
    <child link="fr3_link2" />
    <axis xyz="0 0 1" />
    <limit effort="87.0" lower="-1.8361" upper="1.8361" velocity="2.62" />
    <safety_controller k_position="100.0" k_velocity="40.0" soft_lower_limit="-1.8361" soft_upper_limit="1.8361" />
    <position_based_velocity_limits deceleration_limit="2.585" velocity_offset="0.25" />
    <dynamics D="1" K="7000" damping="0.003" friction="0.2" mu_coulomb="0" mu_viscous="16" />
  </joint>
  
  <link name="fr3_link3">
    <visual name="fr3_link3_visual">
      <geometry>
        <mesh filename="/home/haocheng/kinematics_calibration/meshes/fr3/link3.dae" />
      </geometry>
    </visual>
    <collision name="fr3_link3_collision">
      <geometry>
        <mesh filename="/home/haocheng/kinematics_calibration/meshes/fr3/link3.stl" />
      </geometry>
    </collision>
    <inertial>
      <origin rpy="0 0 0" xyz="0.0407015686 -0.0048200565 -0.0289730823" />
      <mass value="2.2449013699" />
      <inertia ixx="0.02410142547240885" ixy="0.002404694559042109" ixz="-0.002856269270114313" iyy="0.01974053266708178" iyz="-0.002104212683891874" izz="0.019044494482244823" />
    </inertial>
  </link>
  <link name="fr3_link3_sc">
    <collision>
      <origin rpy="0 0 0" xyz="0 0 -0.145" />
      <geometry>
        <cylinder length="0.15" radius="0.09" />
      </geometry>
    </collision>
    <collision>
      <origin xyz="0 0 -0.06999999999999999" />
      <geometry>
        <sphere radius="0.09" />
      </geometry>
    </collision>
    <collision>
      <origin xyz="0 0 -0.21999999999999997" />
      <geometry>
        <sphere radius="0.09" />
      </geometry>
    </collision>
  </link>
  
  <joint name="fr3_link3_sc_joint" type="fixed">
    <origin rpy="0 0 0" />
    <parent link="fr3_link3" />
    <child link="fr3_link3_sc" />
  </joint>
  <link name="fr3_link3_accelerometer_top">
      </link>
  <joint name="fr3_link3_accelerometer_top_joint" type="fixed">
    <origin rpy="-1.5708 0 0" xyz="0.0825 0.05 0" />
    <parent link="fr3_link3" />
    <child link="fr3_link3_accelerometer_top" />
  </joint>
  <link name="fr3_link3_accelerometer_bottom">
      </link>
  <joint name="fr3_link3_accelerometer_bottom_joint" type="fixed">
    <origin rpy="1.5708 0 0" xyz="0.0825 0.04 0" />
    <parent link="fr3_link3" />
    <child link="fr3_link3_accelerometer_bottom" />
  </joint>
  <joint name="fr3_joint3" type="revolute">
    <origin rpy="1.5667768015480488 0.0008469864213074005 0.0025788501485276023" xyz="0.0004143611025519952 -0.3163679192395694 0.0007721355694101926" />
    <parent link="fr3_link2" />
    <child link="fr3_link3" />
    <axis xyz="0 0 1" />
    <limit effort="87.0" lower="-2.9007" upper="2.9007" velocity="2.62" />
    <safety_controller k_position="100.0" k_velocity="40.0" soft_lower_limit="-2.9007" soft_upper_limit="2.9007" />
    <position_based_velocity_limits deceleration_limit="3.5" velocity_offset="0.2005" />
    <dynamics D="1" K="7000" damping="0.003" friction="0.2" mu_coulomb="0" mu_viscous="16" />
  </joint>
  
  <link name="fr3_link4">
    <visual name="fr3_link4_visual">
      <geometry>
        <mesh filename="/home/haocheng/kinematics_calibration/meshes/fr3/link4.dae" />
      </geometry>
    </visual>
    <collision name="fr3_link4_collision">
      <geometry>
        <mesh filename="/home/haocheng/kinematics_calibration/meshes/fr3/link4.stl" />
      </geometry>
    </collision>
    <inertial>
      <origin rpy="0 0 0" xyz="-0.0459100965 0.0630492960 -0.0085187868" />
      <mass value="2.6155955791" />
      <inertia ixx="0.03452998321913202" ixy="0.01322552265982813" ixz="0.01015142998484113" iyy="0.028881621933049058" iyz="-0.0009762833870704552" izz="0.04125471171146641" />
    </inertial>
  </link>
  <link name="fr3_link4_sc">
    <collision>
      <origin rpy="0 0 0" xyz="0 0 0" />
      <geometry>
        <cylinder length="0.12" radius="0.09" />
      </geometry>
    </collision>
    <collision>
      <origin xyz="0 0 0.06" />
      <geometry>
        <sphere radius="0.09" />
      </geometry>
    </collision>
    <collision>
      <origin xyz="0 0 -0.06" />
      <geometry>
        <sphere radius="0.09" />
      </geometry>
    </collision>
  </link>
  
  <joint name="fr3_link4_sc_joint" type="fixed">
    <origin rpy="0 0 0" />
    <parent link="fr3_link4" />
    <child link="fr3_link4_sc" />
  </joint>
  <link name="fr3_link4_accelerometer_top">
      </link>
  <joint name="fr3_link4_accelerometer_top_joint" type="fixed">
    <origin rpy="1.5708 0 0" xyz="-0.0825 0.05 0" />
    <parent link="fr3_link4" />
    <child link="fr3_link4_accelerometer_top" />
  </joint>
  <link name="fr3_link4_accelerometer_bottom">
      </link>
  <joint name="fr3_link4_accelerometer_bottom_joint" type="fixed">
    <origin rpy="-1.5708 0 0" xyz="-0.0825 0.06 0" />
    <parent link="fr3_link4" />
    <child link="fr3_link4_accelerometer_bottom" />
  </joint>
  <joint name="fr3_joint4" type="revolute">
    <origin rpy="1.5702490139085936 0.0013331784547376676 -0.0008429759428888274" xyz="0.08249892692930846 7.69953320542652e-05 0.0003720962457431666" />
    <parent link="fr3_link3" />
    <child link="fr3_link4" />
    <axis xyz="0 0 1" />
    <limit effort="87.0" lower="-3.077" upper="-0.1169" velocity="2.62" />
    <safety_controller k_position="100.0" k_velocity="40.0" soft_lower_limit="-3.077" soft_upper_limit="-0.1169" />
    <position_based_velocity_limits deceleration_limit="4.0" velocity_offset="0.3542" />
    <dynamics D="1" K="7000" damping="0.003" friction="0.2" mu_coulomb="0" mu_viscous="16" />
  </joint>
  
  <link name="fr3_link5">
    <visual name="fr3_link5_visual">
      <geometry>
        <mesh filename="/home/haocheng/kinematics_calibration/meshes/fr3/link5.dae" />
      </geometry>
    </visual>
    <collision name="fr3_link5_collision">
      <geometry>
        <mesh filename="/home/haocheng/kinematics_calibration/meshes/fr3/link5.stl" />
      </geometry>
    </collision>
    <inertial>
      <origin rpy="0 0 0" xyz="-0.0016039605 0.0292536262 -0.0972965990" />
      <mass value="2.3271207594" />
      <inertia ixx="0.051610278463662895" ixy="-0.005715173387783472" ixz="-0.0035673167625872135" iyy="0.04787729713371481" iyz="0.010673985108535986" izz="0.016423625579357254" />
    </inertial>
  </link>
  <link name="fr3_link5_sc">
    <collision>
      <origin rpy="0 0 0" xyz="0 0 -0.26" />
      <geometry>
        <cylinder length="0.1" radius="0.09" />
      </geometry>
    </collision>
    <collision>
      <origin xyz="0 0 -0.21000000000000002" />
      <geometry>
        <sphere radius="0.09" />
      </geometry>
    </collision>
    <collision>
      <origin xyz="0 0 -0.31" />
      <geometry>
        <sphere radius="0.09" />
      </geometry>
    </collision>
    <collision>
      <origin rpy="0 0 0.08" xyz="0 0.08 -0.13" />
      <geometry>
        <cylinder length="0.14" radius="0.055" />
      </geometry>
    </collision>
    <collision>
      <origin xyz="0 0.08 -0.06" />
      <geometry>
        <sphere radius="0.055" />
      </geometry>
    </collision>
    <collision>
      <origin xyz="0 0.08 -0.2" />
      <geometry>
        <sphere radius="0.055" />
      </geometry>
    </collision>
  </link>
  
  <joint name="fr3_link5_sc_joint" type="fixed">
    <origin rpy="0 0 0" />
    <parent link="fr3_link5" />
    <child link="fr3_link5_sc" />
  </joint>
  <link name="fr3_link5_accelerometer_top">
      </link>
  <joint name="fr3_link5_accelerometer_top_joint" type="fixed">
    <origin rpy="-1.5708 0 0" xyz="0 0.11 0" />
    <parent link="fr3_link5" />
    <child link="fr3_link5_accelerometer_top" />
  </joint>
  <link name="fr3_link5_accelerometer_bottom">
      </link>
  <joint name="fr3_link5_accelerometer_bottom_joint" type="fixed">
    <origin rpy="1.5708 0 0" xyz="0 0.1 0" />
    <parent link="fr3_link5" />
    <child link="fr3_link5_accelerometer_bottom" />
  </joint>
  <joint name="fr3_joint5" type="revolute">
    <origin rpy="-1.5721498726877208 -0.00014290889534403448 -0.0012819758064718696" xyz="-0.08243687230014404 0.3843325184097344 -7.681242314871467e-05" />
    <parent link="fr3_link4" />
    <child link="fr3_link5" />
    <axis xyz="0 0 1" />
    <limit effort="12.0" lower="-2.8763" upper="2.8763" velocity="5.26" />
    <safety_controller k_position="100.0" k_velocity="40.0" soft_lower_limit="-2.8763" soft_upper_limit="2.8763" />
    <position_based_velocity_limits deceleration_limit="17.0" velocity_offset="0.5738" />
    <dynamics D="1" K="7000" damping="0.003" friction="0.2" mu_coulomb="0" mu_viscous="16" />
  </joint>
  
  <link name="fr3_link6">
    <visual name="fr3_link6_visual">
      <geometry>
        <mesh filename="/home/haocheng/kinematics_calibration/meshes/fr3/link6.dae" />
      </geometry>
    </visual>
    <collision name="fr3_link6_collision">
      <geometry>
        <mesh filename="/home/haocheng/kinematics_calibration/meshes/fr3/link6.stl" />
      </geometry>
    </collision>
    <inertial>
      <origin rpy="0 0 0" xyz="0.0597131221 -0.0410294666 -0.0101692726" />
      <mass value="1.8170376524" />
      <inertia ixx="0.005412333594383447" ixy="0.006193456360285834" ixz="0.0014219289306117652" iyy="0.014058329545509979" iyz="-0.0013140753741120031" izz="0.016080817924212554" />
    </inertial>
  </link>
  <link name="fr3_link6_sc">
    <collision>
      <origin rpy="0 0 0" xyz="0 0 -0.03" />
      <geometry>
        <cylinder length="0.08" radius="0.08" />
      </geometry>
    </collision>
    <collision>
      <origin xyz="0 0 0.010000000000000002" />
      <geometry>
        <sphere radius="0.08" />
      </geometry>
    </collision>
    <collision>
      <origin xyz="0 0 -0.07" />
      <geometry>
        <sphere radius="0.08" />
      </geometry>
    </collision>
  </link>
  
  <joint name="fr3_link6_sc_joint" type="fixed">
    <origin rpy="0 0 0" />
    <parent link="fr3_link6" />
    <child link="fr3_link6_sc" />
  </joint>
  <joint name="fr3_joint6" type="revolute">
    <origin rpy="1.5635102601005593 -0.00021718181070043167 -0.0001411606680153823" xyz="-0.00012940369565664272 0.0004303357531086777 0.00033271010713557814" />
    <parent link="fr3_link5" />
    <child link="fr3_link6" />
    <axis xyz="0 0 1" />
    <limit effort="12.0" lower="0.4398" upper="4.6216" velocity="4.18" />
    <safety_controller k_position="100.0" k_velocity="40.0" soft_lower_limit="0.4398" soft_upper_limit="4.6216" />
    <position_based_velocity_limits deceleration_limit="5.5" velocity_offset="0.4885" />
    <dynamics D="1" K="7000" damping="0.003" friction="0.2" mu_coulomb="0" mu_viscous="16" />
  </joint>
  
  <link name="fr3_link7">
    <visual name="fr3_link7_visual">
      <geometry>
        <mesh filename="/home/haocheng/kinematics_calibration/meshes/fr3/link7.dae" />
      </geometry>
    </visual>
    <collision name="fr3_link7_collision">
      <geometry>
        <mesh filename="/home/haocheng/kinematics_calibration/meshes/fr3/link7.stl" />
      </geometry>
    </collision>
    <inertial>
      <origin rpy="0 0 0" xyz="0.0045225817 0.0086261921 -0.0161633251" />
      <mass value="0.6271432862" />
      <inertia ixx="0.00021092389150104718" ixy="-2.433299114461931e-05" ixz="4.564480393778983e-05" iyy="0.00017718568002411474" iyz="8.744070223226438e-05" izz="5.993190599659971e-05" />
    </inertial>
  </link>
  <link name="fr3_link7_sc">
    <collision>
      <origin rpy="0 0 0" xyz="0 0 0.01" />
      <geometry>
        <cylinder length="0.14" radius="0.07" />
      </geometry>
    </collision>
    <collision>
      <origin xyz="0 0 0.08" />
      <geometry>
        <sphere radius="0.07" />
      </geometry>
    </collision>
    <collision>
      <origin xyz="0 0 -0.060000000000000005" />
      <geometry>
        <sphere radius="0.07" />
      </geometry>
    </collision>
    <collision>
      <origin rpy="0 1.5707963267948966 0" xyz="0.06 0 0.082" />
      <geometry>
        <cylinder length="0.01" radius="0.06" />
      </geometry>
    </collision>
    <collision>
      <origin xyz="0.065 0 0.082" />
      <geometry>
        <sphere radius="0.06" />
      </geometry>
    </collision>
    <collision>
      <origin xyz="0.055 0 0.082" />
      <geometry>
        <sphere radius="0.06" />
      </geometry>
    </collision>
  </link>
  
  <joint name="fr3_link7_sc_joint" type="fixed">
    <origin rpy="0 0 0.7853981633974483" />
    <parent link="fr3_link7" />
    <child link="fr3_link7_sc" />
  </joint>
  <joint name="fr3_joint7" type="revolute">
    <origin rpy="1.5708619426031787 1.3974772537519443e-07 0.00021471961749753638" xyz="0.08896136814223617 1.6872028485708933e-05 -0.00042788009467542104" />
    <parent link="fr3_link6" />
    <child link="fr3_link7" />
    <axis xyz="0 0 1" />
    <limit effort="12.0" lower="-3.0508" upper="3.0508" velocity="5.26" />
    <safety_controller k_position="100.0" k_velocity="40.0" soft_lower_limit="-3.0508" soft_upper_limit="3.0508" />
    <position_based_velocity_limits deceleration_limit="17.0" velocity_offset="0.4592" />
    <dynamics D="1" K="7000" damping="0.003" friction="0.2" mu_coulomb="0" mu_viscous="16" />
  </joint>
  <link name="fr3_link8" />
  <joint name="fr3_joint8" type="fixed">
    <origin rpy="0 0 0" xyz="0 0 0.110" />
    <parent link="fr3_link7" />
    <child link="fr3_link8" />
  </joint>
  <joint name="fr3_hand_joint" type="fixed">
    <parent link="fr3_link8" />
    <child link="fr3_hand" />
    <origin rpy="0 0 -0.7853981633974483" xyz="0 0 0" />
  </joint>
  
  <link name="fr3_hand">
    <visual>
      <geometry>
        <mesh filename="../meshes/fr3/hand.dae" />
      </geometry>
    </visual>
  </link>
  <link name="fr3_hand_tcp" />
  <joint name="fr3_hand_tcp_joint" type="fixed">
    <origin rpy="0 0 0" xyz="0 0 0.1034" />
    <parent link="fr3_hand" />
    <child link="fr3_hand_tcp" />
  </joint>
  <link name="ball_link">
    <visual>
      <material name="red">
        <color rgba="1 0 0 1" />
      </material>

      <geometry>
        <sphere radius="0.005" />
      </geometry>
    </visual>
  </link>

  <joint name="ball_joint" type="fixed">
    
    <origin rpy="0.0 0.0 0.0" xyz="-0.0009147185555085236 -1.754088059546966e-05 0.03219708441643505" />
    <parent link="fr3_hand_tcp" />
    <child link="ball_link" />
  </joint>
  <link name="fr3_leftfinger">
    <visual>
      <geometry>
        <mesh filename="../meshes/fr3/finger.dae" />
      </geometry>
    </visual>
  </link>
  <link name="fr3_rightfinger">
    <visual>
      <origin rpy="0 0 3.141592653589793" xyz="0 0 0" />
      <geometry>
        <mesh filename="../meshes/fr3/finger.dae" />
      </geometry>
    </visual>
  </link>

    <joint name="fr3_finger_joint1" type="prismatic">
    <parent link="fr3_hand" />
    <child link="fr3_leftfinger" />
    <origin rpy="0 0 0" xyz="0 0 0.0584" />
    <axis xyz="0 1 0" />
    <limit effort="100" lower="0.0" upper="0.04" velocity="0.2" />
    <dynamics damping="0.3" />
  </joint>
  <joint name="fr3_finger_joint2" type="prismatic">
    <parent link="fr3_hand" />
    <child link="fr3_rightfinger" />
    <origin rpy="0 0 0" xyz="0 0 0.0584" />
    <axis xyz="0 -1 0" />
    <limit effort="100" lower="0.0" upper="0.04" velocity="0.2" />
    <mimic joint="fr3_finger_joint1" />
    <dynamics damping="0.3" />
  </joint>
</robot>